<?xml version="1.0" ?>
<!-- =================================================================================== -->
<!-- |    This document was autogenerated by xacro from sia_robot_visual.urdf.xacro    | -->
<!-- |    EDITING THIS FILE BY HAND IS NOT RECOMMENDED                                 | -->
<!-- =================================================================================== -->
<robot name="sia_robot" xmlns:xacro="http://ros.org/wiki/xacro">
  <!--link lenght used in this model for relative coordinate of joint-->
  <!-- link lengths used in model -->
  <!--<xacro:property name="shoulder_height" value="${sia_robot_d1}" />
  <xacro:property name="upper_arm_length" value="${-sia_robot_d2}" />
  <xacro:property name="forearm_length" value="${-sia_robot_d3}" />
  <xacro:property name="wrist_1_length" value="${sia_robot_d4 - 0.1 - 0.2}" />
  <xacro:property name="wrist_2_length" value="${sia_robot_d5}" />
  <xacro:property name="wrist_3_length" value="${sia_robot_d6}" />-->
  <!--world frame is the joint0 frame as default-->
  <link name="link1">
    <visual>
      <origin rpy="0 0 0" xyz="0 0 0.06"/>
      <geometry>
        <mesh filename="package://sia_arm_description/meshes/base_link.dae"/>
      </geometry>
    </visual>
  </link>
  <link name="link2">
    <visual>
      <origin rpy="0 0 0" xyz="0 0 -0.08082"/>
      <geometry>
        <mesh filename="package://sia_arm_description/meshes/shoulder_link.dae"/>
      </geometry>
    </visual>
  </link>
  <link name="link3">
    <visual>
      <origin rpy="-1.57079632679 0 -1.57079632679" xyz="0.32 0 0"/>
      <geometry>
        <mesh filename="package://sia_arm_description/meshes/upper_arm_link.dae"/>
      </geometry>
    </visual>
  </link>
  <link name="link4">
    <visual>
      <origin rpy="-1.57079632679 0 0" xyz="0 0.092452 0"/>
      <geometry>
        <mesh filename="package://sia_arm_description/meshes/forearm_link.dae"/>
      </geometry>
    </visual>
  </link>
  <link name="link5">
    <visual>
      <origin rpy="0 0 0" xyz=" 0 0 -0.08225"/>
      <geometry>
        <mesh filename="package://sia_arm_description/meshes/wrist_1_link.dae"/>
      </geometry>
    </visual>
  </link>
  <link name="link6">
    <visual>
      <origin rpy="-1.57079632679 0 0" xyz="0 0.0922655 0"/>
      <geometry>
        <mesh filename="package://sia_arm_description/meshes/wrist_2_link.dae"/>
      </geometry>
    </visual>
  </link>
  <link name="link7">
    <visual>
      <origin rpy="0 0 0" xyz="0 0 0.049435"/>
      <geometry>
        <mesh filename="package://sia_arm_description/meshes/wrist_3_link.dae"/>
      </geometry>
    </visual>
  </link>
  <joint name="joint1" type="revolute">
    <parent link="link1"/>
    <child link="link2"/>
    <!--<origin xyz="0 0 ${shoulder_height}" rpy="0 0 0" />-->
    <origin rpy="0 0 0" xyz="0 0 0.32625"/>
    <axis xyz="0 0 1"/>
    <!--<limit lower="${-pi}" upper="${pi}" effort="150.0" velocity="3.15"/>-->
    <limit effort="150.0" lower="-3.05432619099" upper="3.05432619099" velocity="3.15"/>
  </joint>
  <joint name="joint2" type="revolute">
    <parent link="link2"/>
    <child link="link3"/>
    <origin rpy="1.57079632679 -1.57079632679 0" xyz="0 0 0"/>
    <axis xyz="0 0 1"/>
    <limit effort="150.0" lower="-0.785398163397" upper="0.785398163397" velocity="3.15"/>
  </joint>
  <joint name="joint3" type="revolute">
    <parent link="link3"/>
    <child link="link4"/>
    <origin rpy="0 0 -1.57" xyz="0.64 0 0"/>
    <axis xyz="0 0 1"/>
    <limit effort="150.0" lower="-1.308996939" upper="1.308996939" velocity="3.15"/>
  </joint>
  <joint name="joint4" type="revolute">
    <parent link="link4"/>
    <child link="link5"/>
    <origin rpy="-1.57 0 0" xyz="0 0.184904 0"/>
    <axis xyz="0 0 1"/>
    <limit effort="28.0" lower="-3.05432619099" upper="3.05432619099" velocity="3.2"/>
  </joint>
  <joint name="joint5" type="revolute">
    <parent link="link5"/>
    <child link="link6"/>
    <origin rpy="1.57 0 0" xyz="0 0 0"/>
    <axis xyz="0 0 1"/>
    <limit effort="28.0" lower="-1.308996939" upper="1.308996939" velocity="3.2"/>
  </joint>
  <joint name="joint6" type="revolute">
    <parent link="link6"/>
    <child link="link7"/>
    <origin rpy="-1.57 0 0" xyz="0 0.184531 0"/>
    <axis xyz="0 0 1"/>
    <limit effort="28.0" lower="-3.05432619099" upper="3.05432619099" velocity="3.2"/>
  </joint>
  <link name="eef">
    <visual>
      <origin rpy="0 0 0" xyz="0 0 -0.1"/>
      <geometry>
        <cylinder length="0.2" radius="0.05"/>
      </geometry>
    </visual>
  </link>
  <joint name="joint7" type="fixed">
    <parent link="link7"/>
    <child link="eef"/>
    <origin rpy="0 0 0" xyz="0 0 0.29887"/>
    <axis xyz="0 0 1"/>
  </joint>
</robot>
